Workbook

Sheet Main
A1: State | B1: Locality | C1: Region | D1: Local Government Area | E1: Council Seat | F1: Year Established | G1: Year Establised (City) | H1: Land Area km² | I1: Sq Miles | J1: Population 2021 | K1: Population Density 2021 | L1: Population 2022 | M1: Population Density 2022 | N1: Councillors (2022) | O1: Main Website | P1: Web Mapping Link | Q1: Spatial Data Link | R1: Notes | S1: Principal Town | T1: AU TOWNS LGA MATCH | U1: Match in AU Towns? | V1: Searchable | W1: Main Link
A2: ACT | B2: Metropolitan | C2: Australian Capital Territory | D2: Australian Capital Territory | T2: Unincorporated | U2: ACT,Unincorporated | V2: Australian Capital Territory | W2: =IF(A2="NSW",_xlfn.TEXTJOIN("",TRUE,'State Sites'!B$2,Main!V2),"")
A3: NSW | B3: Metropolitan | C3: Greater Sydney | D3: Bayside Council | E3: Rockdale Town Hall | F3: 13 January 1871 (as Rockdale Municipality) | G3: 9 September 2016[3] | H3: 50 | I3: 19 | T3: Bayside | U3: NSW,Bayside | V3: bayside-council | W3: =IF(A3="NSW",_xlfn.TEXTJOIN("",TRUE,'State Sites'!B$2,Main!V3),"") -> https://data.nsw.gov.au/data/organization/bayside-council
F4: 29 March 1888 (as Borough of Botany) | V4: 0 | W4: =IF(A4="NSW",_xlfn.TEXTJOIN("",TRUE,'State Sites'!B$2,Main!V4),"")
A5: NSW | B5: Metropolitan | C5: Greater Sydney | D5: Blacktown | E5: Blacktown | F5: 6 March 1906 (Shire)[4] | G5: 7 March 1979 | H5: 240 | I5: 93 | T5: Blacktown | U5: NSW,Blacktown | V5: blacktown-city-council | W5: =IF(A5="NSW",_xlfn.TEXTJOIN("",TRUE,'State Sites'!B$2,Main!V5),"") -> https://data.nsw.gov.au/data/organization/blacktown-city-council
A6: NSW | B6: Metropolitan | C6: Greater Sydney | D6: Burwood | E6: Burwood | F6: 27 March 1874[5] | G6: n/a | H6: 7.1 | I6: 2.7 | T6: Burwood | U6: NSW,Burwood | V6: burwood-council | W6: =IF(A6="NSW",_xlfn.TEXTJOIN("",TRUE,'State Sites'!B$2,Main!V6),"") -> https://data.nsw.gov.au/data/organization/burwood-council
A7: NSW | B7: Metropolitan | C7: Greater Sydney | D7: Camden Council | E7: Oran Park | F7: 6 February 1889[6] | G7: n/a | H7: 201 | I7: 78 | T7: Camden | U7: NSW,Camden | V7: camden-council | W7: =IF(A7="NSW",_xlfn.TEXTJOIN("",TRUE,'State Sites'!B$2,Main!V7),"") -> https://data.nsw.gov.au/data/organization/camden-council
A8: NSW | B8: Metropolitan | C8: Greater Sydney | D8: Campbelltown | E8: Campbelltown | F8: 21 January 1882[7] | G8: 4 May 1968 | H8: 312 | I8: 120 | T8: Campbelltown | U8: NSW,Campbelltown | V8: campbelltown-city-council | W8: =IF(A8="NSW",_xlfn.TEXTJOIN("",TRUE,'State Sites'!B$2,Main!V8),"") -> https://data.nsw.gov.au/data/organization/campbelltown-city-council
A9: NSW | B9: Metropolitan | C9: Greater Sydney | D9: Canada Bay | E9: Drummoyne | F9: 11 August 1883 (Municipal District of Concord)[8] | G9: December 2000 | H9: 20 | I9: 7.7 | T9: Canada Bay | U9: NSW,Canada Bay | V9: city-of-canada-bay-council | W9: =IF(A9="NSW",_xlfn.TEXTJOIN("",TRUE,'State Sites'!B$2,Main!V9),"") -> https://data.nsw.gov.au/data/organization/city-of-canada-bay-council
F10: 18 January 1890 (Borough of Drummoyne) | V10: 0 | W10: =IF(A10="NSW",_xlfn.TEXTJOIN("",TRUE,'State Sites'!B$2,Main!V10),"")
A11: NSW | B11: Metropolitan | C11: Greater Sydney | D11: Canterbury-Bankstown | E11: Bankstown | F11: 17 March 1879 (Municipal District of Canterbury) | G11: 12 May 2016[9] | H11: 110 | I11: 42 | T11: Canterbury-Bankstown | U11: NSW,Canterbury-Bankstown | V11: canterbury-bankstown-council | W11: =IF(A11="NSW",_xlfn.TEXTJOIN("",TRUE,'State Sites'!B$2,Main!V11),"") -> https://data.nsw.gov.au/data/organization/canterbury-bankstown-council
F12: 7 September 1895 (Municipal District of Bankstown) | V12: 0 | W12: =IF(A12="NSW",_xlfn.TEXTJOIN("",TRUE,'State Sites'!B$2,Main!V12),"")
A13: NSW | B13: Metropolitan | C13: Greater Sydney | D13: Cumberland | E13: Merrylands | F13: 9 July 1872 | G13: 12 May 2016[10] | H13: 72 | I13: 28 | T13: Cumberland | U13: NSW,Cumberland | V13: cumberland-council | W13: =IF(A13="NSW",_xlfn.TEXTJOIN("",TRUE,'State Sites'!B$2,Main!V13),"") -> https://data.nsw.gov.au/data/organization/cumberland-council
F14: (as the Prospect and Sherwood Municipal District) | V14: 0 | W14: =IF(A14="NSW",_xlfn.TEXTJOIN("",TRUE,'State Sites'!B$2,Main!V14),"")
A15: NSW | B15: Metropolitan | C15: Greater Sydney | D15: Fairfield | E15: Wakeley | F15: 11 December 1888 | G15: 18 May 1979 | H15: 102 | I15: 39 | T15: Fairfield | U15: NSW,Fairfield | V15: fairfield-city-council | W15: =IF(A15="NSW",_xlfn.TEXTJOIN("",TRUE,'State Sites'!B$2,Main!V15),"") -> https://data.nsw.gov.au/data/organization/fairfield-city-council
F16: (as the Smithfield and Fairfield Municipal District) | V16: 0 | W16: =IF(A16="NSW",_xlfn.TEXTJOIN("",TRUE,'State Sites'!B$2,Main!V16),"")
A17: NSW | B17: Metropolitan | C17: Greater Sydney | D17: Georges River Council | E17: Hurstville | F17: 22 December 1885 (as the Kogarah Municipality) | G17: 12 May 2016[11] | H17: 38 | I17: 15 | T17: Georges River | U17: NSW,Georges River | V17: georges-river-council | W17: =IF(A17="NSW",_xlfn.TEXTJOIN("",TRUE,'State Sites'!B$2,Main!V17),"") -> https://data.nsw.gov.au/data/organization/georges-river-council
F18: 25 March 1887 | V18: 0 | W18: =IF(A18="NSW",_xlfn.TEXTJOIN("",TRUE,'State Sites'!B$2,Main!V18),"")
F19: (Municipal District of Hurstville) | V19: 0 | W19: =IF(A19="NSW",_xlfn.TEXTJOIN("",TRUE,'State Sites'!B$2,Main!V19),"")
A20: NSW | B20: Metropolitan | C20: Greater Sydney | D20: Hornsby Shire | E20: Hornsby | F20: 6 March 1906[4] | G20: n/a | H20: 455 | I20: 176 | T20: Hornsby | U20: NSW,Hornsby | V20: hornsby-shire-council | W20: =IF(A20="NSW",_xlfn.TEXTJOIN("",TRUE,'State Sites'!B$2,Main!V20),"") -> https://data.nsw.gov.au/data/organization/hornsby-shire-council
A21: NSW | B21: Metropolitan | C21: Greater Sydney | D21: Hunter's Hill | E21: Hunters Hill | F21: 7 January 1861[12] | G21: n/a | H21: 5.7 | I21: 2.2 | T21: Hunters Hill | U21: NSW,Hunters Hill | V21: Hunter's Hill | W21: =IF(A21="NSW",_xlfn.TEXTJOIN("",TRUE,'State Sites'!B$2,Main!V21),"") -> https://data.nsw.gov.au/data/organization/Hunter's Hill
A22: NSW | B22: Metropolitan | C22: Greater Sydney | D22: Inner West Council | E22: Ashfield, Leichhardt, Petersham | F22: 1 November 1861 (Municipality of Marrickville) | G22: 12 May 2016[13] | H22: 35 | I22: 14 | T22: Inner West | U22: NSW,Inner West | V22: inner-west-council | W22: =IF(A22="NSW",_xlfn.TEXTJOIN("",TRUE,'State Sites'!B$2,Main!V22),"") -> https://data.nsw.gov.au/data/organization/inner-west-council
F23: 28 December 1871 (Borough of Ashfield) | V23: 0 | W23: =IF(A23="NSW",_xlfn.TEXTJOIN("",TRUE,'State Sites'!B$2,Main!V23),"")
F24: 29 December 1871 (Municipal District of Leichhardt) | V24: 0 | W24: =IF(A24="NSW",_xlfn.TEXTJOIN("",TRUE,'State Sites'!B$2,Main!V24),"")
A25: NSW | B25: Metropolitan | C25: Greater Sydney | D25: Ku-ring-gai Council | E25: Gordon | F25: 1906 (Shire)[4] 1928 (Municipality) | G25: n/a | H25: 85 | I25: 33 | T25: Ku-ring-gai | U25: NSW,Ku-ring-gai | V25: ku-ring-gai-council | W25: =IF(A25="NSW",_xlfn.TEXTJOIN("",TRUE,'State Sites'!B$2,Main!V25),"") -> https://data.nsw.gov.au/data/organization/ku-ring-gai-council
A26: NSW | B26: Metropolitan | C26: Greater Sydney | D26: Lane Cove Council | E26: Lane Cove | F26: 11 February 1895 (Borough of Lane Cove)[14] | G26: n/a | H26: 11 | I26: 4.2 | T26: Lane Cove | U26: NSW,Lane Cove | V26: lane-cove-municipal-council | W26: =IF(A26="NSW",_xlfn.TEXTJOIN("",TRUE,'State Sites'!B$2,Main!V26),"") -> https://data.nsw.gov.au/data/organization/lane-cove-municipal-council
A27: NSW | B27: Metropolitan | C27: Greater Sydney | D27: Liverpool | E27: Liverpool | F27: 27 June 1872 (Municipal District) | G27: 9 November 1960 | H27: 306 | I27: 118 | T27: Liverpool | U27: NSW,Liverpool | V27: liverpool-city-council | W27: =IF(A27="NSW",_xlfn.TEXTJOIN("",TRUE,'State Sites'!B$2,Main!V27),"") -> https://data.nsw.gov.au/data/organization/liverpool-city-council
A28: NSW | B28: Metropolitan | C28: Greater Sydney | D28: Mosman Council | E28: Mosman | F28: 11 April 1893 (as Borough of Mosman)[15] | G28: n/a | H28: 8.7 | I28: 3.4 | T28: Mosman | U28: NSW,Mosman | V28: mosman-municipal-council | W28: =IF(A28="NSW",_xlfn.TEXTJOIN("",TRUE,'State Sites'!B$2,Main!V28),"") -> https://data.nsw.gov.au/data/organization/mosman-municipal-council
A29: NSW | B29: Metropolitan | C29: Greater Sydney | D29: North Sydney Council | E29: North Sydney Council Chambers | F29: 31 July 1890 (as Borough of North Sydney)[16] | G29: n/a | H29: 11 | I29: 4.2 | T29: North Sydney | U29: NSW,North Sydney | V29: north-sydney-council | W29: =IF(A29="NSW",_xlfn.TEXTJOIN("",TRUE,'State Sites'!B$2,Main!V29),"") -> https://data.nsw.gov.au/data/organization/north-sydney-council
A30: NSW | B30: Metropolitan | C30: Greater Sydney | D30: Northern Beaches Council | E30: Dee Why | F30: 6 January 1877 (Manly Municipality) | G30: 12 May 2016[17] | H30: 254 | I30: 98 | T30: Northern Beaches | U30: NSW,Northern Beaches | V30: northern-beaches-council | W30: =IF(A30="NSW",_xlfn.TEXTJOIN("",TRUE,'State Sites'!B$2,Main!V30),"") -> https://data.nsw.gov.au/data/organization/northern-beaches-council
F31: 7 March 1906 (as Warringah Shire)[4] | V31: 0 | W31: =IF(A31="NSW",_xlfn.TEXTJOIN("",TRUE,'State Sites'!B$2,Main!V31),"")
F32: 1 May 1992 (as Pittwater Municipality) | V32: 0 | W32: =IF(A32="NSW",_xlfn.TEXTJOIN("",TRUE,'State Sites'!B$2,Main!V32),"")
A33: NSW | B33: Metropolitan | C33: Greater Sydney | D33: Parramatta | E33: Parramatta Town Hall | F33: 27 November 1861 (Municipality) | G33: 12 May 2016[18] | H33: 84 | I33: 32 | T33: Parramatta | U33: NSW,Parramatta | V33: city-of-parramatta-council | W33: =IF(A33="NSW",_xlfn.TEXTJOIN("",TRUE,'State Sites'!B$2,Main!V33),"") -> https://data.nsw.gov.au/data/organization/city-of-parramatta-council
A34: NSW | B34: Metropolitan | C34: Greater Sydney | D34: Penrith | E34: Penrith | F34: 12 May 1871 (Municipality)[19] | G34: 21 October 1959 | H34: 405 | I34: 156 | T34: Penrith | U34: NSW,Penrith | V34: penrith-city-council | W34: =IF(A34="NSW",_xlfn.TEXTJOIN("",TRUE,'State Sites'!B$2,Main!V34),"") -> https://data.nsw.gov.au/data/organization/penrith-city-council
A35: NSW | B35: Metropolitan | C35: Greater Sydney | D35: Randwick | E35: Randwick Town Hall | F35: 23 February 1859[20] | G35: 1 July 1990[21] | H35: 36 | I35: 14 | T35: Randwick | U35: NSW,Randwick | V35: randwick-city-council | W35: =IF(A35="NSW",_xlfn.TEXTJOIN("",TRUE,'State Sites'!B$2,Main!V35),"") -> https://data.nsw.gov.au/data/organization/randwick-city-council
A36: NSW | B36: Metropolitan | C36: Greater Sydney | D36: Ryde | E36: Ryde | F36: 12 November 1870 (Municipal district) | G36: 1 January 1992 | H36: 41 | I36: 16 | T36: Ryde | U36: NSW,Ryde | V36: city-of-ryde | W36: =IF(A36="NSW",_xlfn.TEXTJOIN("",TRUE,'State Sites'!B$2,Main!V36),"") -> https://data.nsw.gov.au/data/organization/city-of-ryde
A37: NSW | B37: Metropolitan | C37: Greater Sydney | D37: Strathfield | E37: Strathfield | F37: 2 June 1885 | G37: n/a | H37: 14 | I37: 5.4 | T37: Strathfield | U37: NSW,Strathfield | V37: strathfield-municipal-council | W37: =IF(A37="NSW",_xlfn.TEXTJOIN("",TRUE,'State Sites'!B$2,Main!V37),"") -> https://data.nsw.gov.au/data/organization/strathfield-municipal-council
A38: NSW | B38: Metropolitan | C38: Greater Sydney | D38: Sutherland Shire | E38: Sutherland | F38: 6 March 1906[4] | G38: n/a | H38: 334 | I38: 129 | T38: Sutherland Shire | U38: NSW,Sutherland Shire | V38: sutherland-shire-council | W38: =IF(A38="NSW",_xlfn.TEXTJOIN("",TRUE,'State Sites'!B$2,Main!V38),"") -> https://data.nsw.gov.au/data/organization/sutherland-shire-council
A39: NSW | B39: Metropolitan | C39: Greater Sydney | D39: Sydney | E39: Sydney Town Hall | F39: n/a | G39: 20 July 1842[22] | H39: 27 | I39: 10 | T39: Sydney | U39: NSW,Sydney | V39: Sydney | W39: =IF(A39="NSW",_xlfn.TEXTJOIN("",TRUE,'State Sites'!B$2,Main!V39),"") -> https://data.nsw.gov.au/data/organization/Sydney
A40: NSW | B40: Metropolitan | C40: Greater Sydney | D40: The Hills Shire | E40: Norwest | F40: 6 March 1906[4] | G40: n/a | H40: 386 | I40: 149 | T40: The Hills Shire | U40: NSW,The Hills Shire | V40: the-hills-shire-council | W40: =IF(A40="NSW",_xlfn.TEXTJOIN("",TRUE,'State Sites'!B$2,Main!V40),"") -> https://data.nsw.gov.au/data/organization/the-hills-shire-council
...

Sheet State Sites
A1: State | B1: Spatial Website
A2: NSW | B2: https://data.nsw.gov.au/data/organization/
